2016-06-17T11:07:47+02:00 seafile-www-02 2016-06-17 17:07:47,050 [ERROR] django.request:256 handle_uncaught_exception Internal Server Error: /api2/events/#012Traceback (most recent call last):#012  File "/data/seafile/seafile-pro-server-5.1.8/seahub/thirdpart/Django-1.8.10-py2.7.egg/django/core/handlers/base.py", line 132, in get_response#012    response = wrapped_callback(request, *callback_args, **callback_kwargs)#012  File "/data/seafile/seafile-pro-server-5.1.8/seahub/thirdpart/Django-1.8.10-py2.7.egg/django/views/decorators/csrf.py", line 58, in wrapped_view#012    return view_func(*args, **kwargs)#012  File "/data/seafile/seafile-pro-server-5.1.8/seahub/thirdpart/Django-1.8.10-py2.7.egg/django/views/generic/base.py", line 71, in view#012    return self.dispatch(request, *args, **kwargs)#012  File "/data/seafile/seafile-pro-server-5.1.8/seahub/thirdpart/djangorestframework-3.3.2-py2.7.egg/rest_framework/views.py", line 466, in dispatch#012    response = self.handle_exception(exc)#012  File "/data/seafile/seafile-pro-server-5.1.8/seahub/thirdpart/djangorestframework-3.3.2-py2.7.egg/rest_framework/views.py", line 463, in dispatch#012    response = handler(request, *args, **kwargs)#012  File "/data/seafile/seafile-pro-server-5.1.8/seahub/seahub/api2/views.py", line 3346, in get#012    url, is_default, date_uploaded = api_avatar_url(d['author'], size)#012ValueError: too many values to unpack

2016-06-17T10:34:38+02:00 seafile-www-02 2016-06-17 16:34:38,377 [WARNING] django.request:170 get_response Not Found: /apple-touch-icon-precomposed.png

2016-06-17T11:20:43+02:00 seafile-www-02 2016-06-17 17:20:43,743 [WARNING] django.request:98 _reject Forbidden (Referer checking failed - no Referer.): /

2016-06-15T14:41:28+02:00 seafile-www-04 2016-06-15 20:41:28,672 [WARNING] seahub.auth.views:172 login Login attempt limit reached, try freeze the user, email/username: kerthhorst.zentrale%40lbbnet.de, ip: 83.243.48.54, attemps: 13

2016-06-15T14:39:16+02:00 seafile-www-04 2016-06-15 20:39:16,364 [WARNING] seahub.auth.views:182 login Login attempt limit reached, freeze the user email/username: kerthhorst.zentrale@lbbnet.de, ip: 83.243.48.54, attemps: 7

2016-06-14T16:03:28+02:00 seafile-www-01 2016-06-14 22:03:28,058 [ERROR] seahub.thumbnail.utils:80 generate_thumbnail cannot identify image file

2016-06-08T18:55:50+02:00 seafile-www-02 2016-06-09 00:55:50,322 [ERROR] seahub.thumbnail.utils:80 generate_thumbnail image file is truncated (1 bytes not processed)

2016-06-09T12:16:00+02:00 seafile-www-01 2016-06-09 18:16:00,941 [ERROR] seahub.thumbnail.views:76 latest_entry [Errno 2] No such file or directory: '/data/seafile/seafile-pro-server-5.1.6/seahub/seahub/../../../seahub-data/thumbnail/48/d205fc1b6c0df34151129f252ccb71d16fe02460'

2016-06-14T21:36:47+02:00 seafile-www-01 shibboleth-sp: 1465933007 ERROR Shibboleth.Apache [11923] shib_check_user: SAML response contained an error.

2016-06-16T15:13:28+02:00 seafile-www-01 2016-06-16 21:13:28,740 [ERROR] seahub.api2.endpoints.dir_shared_items:321 put Can not share repo to myself


Queries:
tail -n 100 seafile.rlp.net.log | perl -p -e "s/^.*seafile-www-0[1-4] .*\[[0-9]*\]: //g" | sort -u
less seafile.rlp.net.log | sort -u | egrep ".*ERROR.*" | egrep -v ".*ERROR.*256"
less seafile.rlp.net.log | sort -u | egrep ".*WARNING.*" | egrep -v ".*WARNING.*170" 
